Workbook

Sheet Call List
A1: Owner Name | B1: Owner Role | C1: Owner Direct Line | D1: Owner Mailing | E1: Match Quality | F1: # | G1: Priority | H1: Business Name | I1: Category | J1: Business Phone | K1: Website Gap | L1: Website | M1: Site Platform | N1: Mobile OK | O1: Rating | P1: Reviews | Q1: Neg % | R1: GBP Unclaimed | S1: Photos | T1: Neighborhood | U1: Street | V1: Zip | W1: GBP Link | X1: Call Status | Y1: Attempts | Z1: Last Called | AA1: Spoke With | AB1: Their Role | AC1: Outcome | AD1: Next Step | AE1: Follow Up Date | AF1: Notes
F2: 1 | G2: 85 | H2: West Wing | I2: Extended stay hotel | J2: (813) 559-8000 | K2: OTA listing only | L2: https://rapidhotels.com/WestWing | O2: 4.2 | P2: 1054 | Q2: 0.113 | R2: YES | S2: 1000 | T2: University Square | U2: 2501 E Fowler Ave | W2: https://www.google.com/maps/search/?api=1&query=West%20Wing&query_place_id=ChIJU3whOajHwogRCcUPSkExvP8 | X2: Not called | Y2: 0
F3: 2 | G3: 82 | H3: Casa Loma Motel | I3: Hotel | J3: (813) 234-3871 | K3: No website | O3: 3.6 | P3: 133 | Q3: 0.226 | R3: YES | S3: 17 | T3: Old Seminole Heights | U3: 6500 N Nebraska Ave | W3: https://www.google.com/maps/search/?api=1&query=Casa%20Loma%20Motel&query_place_id=ChIJAyxw8JjGwogR54BdEl0QeZQ | X3: Not called | Y3: 0
F4: 3 | G4: 82 | H4: Village Motel | I4: Motel | J4: (813) 626-6541 | K4: No website | O4: 3.5 | P4: 70 | Q4: 0.243 | R4: YES | S4: 6 | T4: Northeast Tampa | U4: 4100 E Hillsborough Ave | W4: https://www.google.com/maps/search/?api=1&query=Village%20Motel&query_place_id=ChIJ2bgaYXXGwogR_K8nSHrztdg | X4: Not called | Y4: 0
F5: 4 | G5: 77 | H5: Oaks Motel | I5: Motel | J5: (813) 229-1281 | K5: No website | O5: 3.1 | P5: 138 | Q5: 0.377 | R5: YES | S5: 21 | T5: Ybor City | U5: 3801 N Nebraska Ave | W5: https://www.google.com/maps/search/?api=1&query=Oaks%20Motel&query_place_id=ChIJIYY5-D7EwogReop0NpHboOM | X5: Not called | Y5: 0
F6: 5 | G6: 77 | H6: El Rancho Motel | I6: Hotel | J6: (813) 232-6251 | K6: No website | O6: 3.1 | P6: 111 | Q6: 0.396 | R6: YES | S6: 14 | T6: Old Seminole Heights | U6: 7100 N Nebraska Ave | W6: https://www.google.com/maps/search/?api=1&query=El%20Rancho%20Motel&query_place_id=ChIJCSglsZfGwogRDnCt8H2jF3Q | X6: Not called | Y6: 0
F7: 6 | G7: 77 | H7: Harbor Lite Motel | I7: Motel | J7: (813) 876-6215 | K7: No website | O7: 4.1 | P7: 111 | S7: 6 | T7: Oakford Park | U7: 3301 W Kennedy Blvd | W7: https://www.google.com/maps/search/?api=1&query=Harbor%20Lite%20Motel&query_place_id=ChIJz2h7MA3DwogRFbWp6t4TlBs | X7: Not called | Y7: 0
F8: 7 | G8: 77 | H8: Mac's Motel | I8: Motel | J8: (813) 238-3285 | K8: No website | O8: 2.9 | P8: 67 | Q8: 0.448 | R8: YES | S8: 6 | T8: Old Seminole Heights | U8: 5605 N Nebraska Ave | W8: https://www.google.com/maps/search/?api=1&query=Mac's%20Motel&query_place_id=ChIJp35-fiDEwogRJQsJJVAjkUc | X8: Not called | Y8: 0
F9: 8 | G9: 77 | H9: Swan Motel | I9: Hotel | J9: (813) 238-5707 | K9: No website | O9: 3.2 | P9: 63 | Q9: 0.365 | R9: YES | S9: 5 | T9: Old Seminole Heights | U9: 6407 N Nebraska Ave | W9: https://www.google.com/maps/search/?api=1&query=Swan%20Motel&query_place_id=ChIJVffc4ZjGwogRbD7Nxi2fYP0 | X9: Not called | Y9: 0
F10: 9 | G10: 77 | H10: Alamo Motel | I10: Motel | J10: (813) 238-0090 | K10: No website | O10: 2.6 | P10: 59 | Q10: 0.576 | R10: YES | S10: 13 | T10: Old Seminole Heights | U10: 6110 N Nebraska Ave | W10: https://www.google.com/maps/search/?api=1&query=Alamo%20Motel&query_place_id=ChIJ-1ElPZ_GwogRIIra3PbXH7s | X10: Not called | Y10: 0
F11: 10 | G11: 75 | H11: Sunset Inn at Busch Gardens | I11: Indoor lodging | J11: (813) 931-3313 | K11: No website | O11: 3.5 | P11: 282 | S11: 45 | U11: 2106 E Busch Blvd | W11: https://www.google.com/maps/search/?api=1&query=Sunset%20Inn%20at%20Busch%20Gardens&query_place_id=ChIJv0mq2PnGwogRYhO6c71sSo0 | X11: Not called | Y11: 0
F12: 11 | G12: 75 | H12: The Rex Motel | I12: Motel | J12: (813) 874-8664 | K12: No website | O12: 3.8 | P12: 33 | Q12: 0.273 | R12: YES | S12: 5 | T12: Northwest Tampa | U12: 5406 Felice Ave | W12: https://www.google.com/maps/search/?api=1&query=The%20Rex%20Motel&query_place_id=ChIJQ9GnwePDwogRYRfHRheweqA | X12: Not called | Y12: 0
F13: 12 | G13: 70 | H13: Garden View Motel | I13: Motel | J13: (813) 933-3958 | K13: No website | O13: 3.3 | P13: 233 | S13: 64 | U13: 2500 E Busch Blvd | W13: https://www.google.com/maps/search/?api=1&query=Garden%20View%20Motel&query_place_id=ChIJ7w8t8FfGwogR2TIfBJ0Q_pk | X13: Not called | Y13: 0
F14: 13 | G14: 70 | H14: Alaska Motel | I14: Motel | J14: (813) 374-2155 | K14: No website | O14: 3.1 | P14: 13 | Q14: 0.462 | R14: YES | S14: 2 | T14: Southeast Seminole Heights | U14: 1307 E Hillsborough Ave | W14: https://www.google.com/maps/search/?api=1&query=Alaska%20Motel&query_place_id=ChIJyboEHKTFwogRJ4VfqFISi9I | X14: Not called | Y14: 0
F15: 14 | G15: 67 | H15: Orange Motel | I15: Motel | J15: (813) 231-4603 | K15: No website | O15: 2.3 | P15: 158 | Q15: 0.62 | S15: 16 | T15: Old Seminole Heights | U15: 7800 N Nebraska Ave | W15: https://www.google.com/maps/search/?api=1&query=Orange%20Motel&query_place_id=ChIJ0xeysZXGwogRl6eLG4aDM34 | X15: Not called | Y15: 0
F16: 15 | G16: 67 | H16: Sunset Inn Motel | I16: Hotel | J16: (813) 626-4313 | K16: No website | O16: 3.1 | P16: 129 | Q16: 0.372 | S16: 21 | U16: 4712 E Hillsborough Ave | W16: https://www.google.com/maps/search/?api=1&query=Sunset%20Inn%20Motel&query_place_id=ChIJixWQHQrGwogRut_zTTMnvKM | X16: Not called | Y16: 0
F17: 16 | G17: 67 | H17: Downtown Motel | I17: Motel | J17: (813) 224-9582 | K17: No website | O17: 2.9 | P17: 126 | S17: 17 | T17: Tampa Heights | U17: 2739 N Florida Ave | W17: https://www.google.com/maps/search/?api=1&query=Downtown%20Motel&query_place_id=ChIJn_8izG7EwogRJRHpxk96Ts0 | X17: Not called | Y17: 0
F18: 17 | G18: 67 | H18: Jayhawk Motel | I18: Motel | J18: (813) 229-9475 | K18: No website | O18: 2.8 | P18: 111 | Q18: 0.514 | S18: 19 | T18: Ybor City | U18: 3415 N Nebraska Ave | W18: https://www.google.com/maps/search/?api=1&query=Jayhawk%20Motel&query_place_id=ChIJZfE1gEDEwogRXgyypNhn6zA | X18: Not called | Y18: 0
F19: 18 | G19: 67 | H19: Royal Palm Motel | I19: Hotel | J19: (813) 238-9478 | K19: No website | O19: 2.9 | P19: 101 | Q19: 0.455 | S19: 15 | T19: Old Seminole Heights | U19: 5809 N Nebraska Ave #7127 | W19: https://www.google.com/maps/search/?api=1&query=Royal%20Palm%20Motel&query_place_id=ChIJk9KttZ_GwogREhLCFgnFk5g | X19: Not called | Y19: 0
F20: 19 | G20: 67 | H20: University Motel | I20: Hotel | J20: (813) 931-4566 | K20: No website | O20: 3 | P20: 83 | Q20: 0.373 | S20: 9 | U20: 9408 N Nebraska Ave | W20: https://www.google.com/maps/search/?api=1&query=University%20Motel&query_place_id=ChIJF_XTsOfGwogRKt7MVITsYe8 | X20: Not called | Y20: 0
F21: 20 | G21: 65 | H21: Tampa Inn Near Busch Gardens | I21: Hotel | J21: (813) 933-6471 | K21: OTA listing only | L21: https://www.tampainnbuschgardens.info/ | O21: 2.4 | P21: 1544 | Q21: 0.597 | S21: 1200 | U21: 2901 E Busch Blvd | W21: https://www.google.com/maps/search/?api=1&query=Tampa%20Inn%20Near%20Busch%20Gardens&query_place_id=ChIJEa4TrfrGwogRwyU4j6_bzHA | X21: Not called | Y21: 0
F22: 21 | G22: 62 | H22: Macdill Motel | I22: Motel | J22: (813) 837-6864 | K22: No website | O22: 3 | P22: 138 | Q22: 0.435 | S22: 50 | T22: South Tampa | U22: Macdill Motel, 6227 S Dale Mabry Hwy | W22: https://www.google.com/maps/search/?api=1&query=Macdill%20Motel&query_place_id=ChIJ5ShCcu_cwogR_fjNWGIxZ_8 | X22: Not called | Y22: 0
F23: 22 | G23: 62 | H23: Mayflower Motel | I23: Hotel | J23: (813) 565-8502 | K23: No website | O23: 3.1 | P23: 85 | Q23: 0.376 | S23: 33 | T23: Old Seminole Heights | U23: 7510 N Florida Ave | W23: https://www.google.com/maps/search/?api=1&query=Mayflower%20Motel&query_place_id=ChIJMTvTW7nGwogR_plYnYVNB5M | X23: Not called | Y23: 0
F24: 23 | G24: 62 | H24: Sunny South Motel | I24: Hotel | J24: (813) 879-2055 | K24: No website | O24: 2.6 | P24: 62 | Q24: 0.548 | S24: 48 | T24: Northwest Tampa | U24: 3206 W Hillsborough Ave | W24: https://www.google.com/maps/search/?api=1&query=Sunny%20South%20Motel&query_place_id=ChIJS4s2zuDDwogRMx_l7LRg-vI | X24: Not called | Y24: 0
F25: 24 | G25: 60 | H25: The Hip Hop Hotels | I25: Hotel | J25: (813) 619-2899 | K25: OTA listing only | L25: https://thehiphophotels.com/ | O25: 4.9 | P25: 17 | Q25: 0 | S25: 52 | U25: 820 E Busch Blvd | W25: https://www.google.com/maps/search/?api=1&query=The%20Hip%20Hop%20Hotels&query_place_id=ChIJa5RF4THHwogRqVeeOguX7-c | X25: Not called | Y25: 0
F26: 25 | G26: 60 | H26: Chestnut Villas | I26: Hotel | J26: (813) 337-6160 | K26: No website | O26: 2.9 | P26: 15 | Q26: 0.533 | S26: 28 | T26: Northeast MacFarlane | U26: 2930 W Chestnut St | W26: https://www.google.com/maps/search/?api=1&query=Chestnut%20Villas&query_place_id=ChIJT1x_SvLDwogR3sDTYJHu7Jg | X26: Not called | Y26: 0
F27: 26 | G27: 60 | H27: Seminole Motel | I27: Motel | J27: (813) 239-2264 | K27: No website | O27: 3.3 | P27: 11 | Q27: 0.273 | S27: 2 | T27: Old Seminole Heights | U27: 7200 N Florida Ave | W27: https://www.google.com/maps/search/?api=1&query=Seminole%20Motel&query_place_id=ChIJ_6hbojXHwogRTf8gilMWTG8 | X27: Not called | Y27: 0
F28: 27 | G28: 40 | H28: Hotel Haya | I28: Hotel | J28: (813) 462-9515 | K28: Has website | L28: https://hotelhaya.com/?utm_source=google&utm_medium=organic&utm_campaign=googlelisting&utm_id=gmb | O28: 4.5 | P28: 1259 | Q28: 0.091 | S28: 1737 | T28: Ybor City | U28: 1412 E 7th Ave | W28: https://www.google.com/maps/search/?api=1&query=Hotel%20Haya&query_place_id=ChIJ2_xFiVrEwogRHOkifwb6NpU | X28: Not called | Y28: 0
F29: 28 | G29: 37 | H29: MacDill AFB Inns | I29: Hotel | J29: (813) 828-4259 | K29: Has website | L29: https://macdillfss.com/macdill-inn-lodging/ | O29: 4.6 | P29: 133 | R29: YES | S29: 115 | U29: 7637 Bayshore Blvd | W29: https://www.google.com/maps/search/?api=1&query=MacDill%20AFB%20Inns&query_place_id=ChIJFQj_v9ndwogRp62ss7wlVM8 | X29: Not called | Y29: 0
F30: 29 | G30: 35 | H30: Sailport Waterfront Suites | I30: Hotel | J30: (855) 651-1841 | K30: Has website | L30: https://www.providentresorts.com/sailport-waterfront-suites-tampa-and-treasure-island/?utm_source=local&utm_campaign=gmb&utm_medium=organic | O30: 4.1 | P30: 3064 | S30: 7445 | T30: Westshore | U30: 2506 N Rocky Point Dr | W30: https://www.google.com/maps/search/?api=1&query=Sailport%20Waterfront%20Suites&query_place_id=ChIJZ_YH9s3pwogR8iNTH5IBaUg | X30: Not called | Y30: 0
F31: 30 | G31: 35 | H31: The Barrymore Hotel Tampa Riverwalk | I31: Hotel | J31: (813) 223-1351 | K31: Has website | L31: https://www.barrymorehotel.com/ | O31: 4 | P31: 2293 | S31: 1811 | T31: Downtown | U31: 111 W Fortune St | W31: https://www.google.com/maps/search/?api=1&query=The%20Barrymore%20Hotel%20Tampa%20Riverwalk&query_place_id=ChIJ1V9kr2LEwogRMW-wiXgjUpA | X31: Not called | Y31: 0
F32: 31 | G32: 35 | H32: Hotel South Tampa & Suites | I32: Hotel | J32: (813) 832-4656 | K32: Has website | L32: https://www.hotelsouthtampa.com/ | O32: 4.2 | P32: 1475 | S32: 744 | T32: South Tampa | U32: 3314 S Dale Mabry Hwy | W32: https://www.google.com/maps/search/?api=1&query=Hotel%20South%20Tampa%20%26%20Suites&query_place_id=ChIJQ70agTHDwogRZgJzIvOtMeI | X32: Not called | Y32: 0
F33: 32 | G33: 30 | H33: Tahitian Inn | I33: Hotel | J33: (813) 877-6721 | K33: Has website | L33: http://www.tahitianinn.com/ | O33: 3.6 | P33: 1418 | Q33: 0.259 | S33: 1075 | T33: Swann Estates | U33: 601 S Dale Mabry Hwy | W33: https://www.google.com/maps/search/?api=1&query=Tahitian%20Inn&query_place_id=ChIJ8Vj56BDDwogRRzlj2Pn6uAE | X33: Not called | Y33: 0
F34: 33 | G34: 30 | H34: Gram’s Place Bed and Hostel | I34: Hostel | J34: (813) 221-0596 | K34: Has website | L34: http://grams-inn-tampa.com/ | O34: 4.4 | P34: 440 | S34: 738 | T34: Tampa Heights | U34: 3109 N Ola Ave | W34: https://www.google.com/maps/search/?api=1&query=Gram%E2%80%99s%20Place%20Bed%20and%20Hostel&query_place_id=ChIJz2XsdW3EwogRp85hhsbx0ng | X34: Not called | Y34: 0
F35: 34 | G35: 30 | H35: Oasis Bay Suites | I35: Hotel | J35: (813) 212-8296 | K35: Has website | L35: https://oasisbaysuites.com/?utm_campaign=gmb | O35: 4.1 | P35: 395 | S35: 516 | T35: Terrace Park | U35: 3001 University Center Dr | W35: https://www.google.com/maps/search/?api=1&query=Oasis%20Bay%20Suites&query_place_id=ChIJaw2NtqzHwogRZ60jq39gLnk | X35: Not called | Y35: 0
F36: 35 | G36: 27 | H36: Open Gate Motel | I36: Motel | J36: (813) 239-3134 | K36: Has website | L36: http://open-gate-motel.edan.io/ | O36: 2.9 | P36: 76 | Q36: 0.434 | R36: YES | S36: 18 | T36: South Seminole Heights | U36: 4810 N Florida Ave | W36: https://www.google.com/maps/search/?api=1&query=Open%20Gate%20Motel&query_place_id=ChIJmwRHJBrEwogREV2NerLZ23o | X36: Not called | Y36: 0
F37: 36 | G37: 25 | H37: Hyde Park Hotel | I37: Hotel | J37: (813) 254-2000 | K37: Has website | L37: http://www.hydeparkhoteltampa.com/ | O37: 3.5 | P37: 305 | S37: 258 | T37: South Tampa | U37: 2105 W Bristol Ave | W37: https://www.google.com/maps/search/?api=1&query=Hyde%20Park%20Hotel&query_place_id=ChIJQdQ_umbDwogR12GtwLicpt4 | X37: Not called | Y37: 0
F38: 37 | G38: 25 | H38: Tampa RV Park Camp Nebraska | I38: RV park | J38: (813) 971-3460 | K38: Has website | L38: http://www.tampa-rv-park-camp-nebraska.com/ | O38: 3.7 | P38: 291 | Q38: 0.234 | S38: 390 | U38: 10314 N Nebraska Ave | W38: https://www.google.com/maps/search/?api=1&query=Tampa%20RV%20Park%20Camp%20Nebraska&query_place_id=ChIJ_QYJaODGwogR82CgRSrg58s | X38: Not called | Y38: 0
F39: 38 | G39: 22 | H39: Economy Inn | I39: Hotel | J39: (813) 933-2665 | K39: Has website | L39: http://economy-inn-tampa.poi.place/ | O39: 2.5 | P39: 152 | Q39: 0.546 | R39: YES | S39: 30 | U39: 1810 E Busch Blvd | W39: https://www.google.com/maps/search/?api=1&query=Economy%20Inn&query_place_id=ChIJgfvdCfrGwogRlsw_naUa8Oc | X39: Not called | Y39: 0
F40: 39 | G40: 22 | H40: Palm Villa Hostel | I40: Hostel | J40: (813) 455-7947 | K40: Has website | L40: https://www.palmvillahostel.com/ | O40: 4.1 | P40: 62 | S40: 170 | T40: Tampa Heights | U40: 801 E Palm Ave | W40: https://www.google.com/maps/search/?api=1&query=Palm%20Villa%20Hostel&query_place_id=ChIJJfSmaV3EwogRqDpRWEvkmCs | X40: Not called | Y40: 0
...

Sheet Dashboard
A1: TAMPA LODGING — CALL LIST
A2: Apify Google Places export 2026-08-28 · search terms: "hotel", "resort"
A4: SCRAPE FUNNEL
A5: Rows scraped | B5: 404
A6: Removed — not lodging | B6: 187
A7: Removed — chain / franchise | B7: 88
A8: Removed — no phone | B8: 60
A9: Removed — under 10 reviews | B9: 23
A10: Removed — closed | B10: 3
A11: WORKABLE LEADS | B11: =B5-SUM(B6:B10) -> 43
A12: Survival rate | B12: =B11/B5 -> 0.10643564
A14: WEBSITE GAP
A15: No website | B15: =COUNTIF('Call List'!$K$2:$K$44,A15) -> 23
A16: OTA listing only | B16: =COUNTIF('Call List'!$K$2:$K$44,A16) -> 3
A17: Social only | B17: =COUNTIF('Call List'!$K$2:$K$44,A17) -> 0
A18: Has website | B18: =COUNTIF('Call List'!$K$2:$K$44,A18) -> 17
A20: SITE PLATFORM (fill as you audit)
A21: Wix | B21: =COUNTIF('Call List'!$M$2:$M$44,A21) -> 0
A22: Squarespace | B22: =COUNTIF('Call List'!$M$2:$M$44,A22) -> 0
A23: GoDaddy | B23: =COUNTIF('Call List'!$M$2:$M$44,A23) -> 0
A24: WordPress | B24: =COUNTIF('Call List'!$M$2:$M$44,A24) -> 0
A25: Weebly | B25: =COUNTIF('Call List'!$M$2:$M$44,A25) -> 0
A26: Custom | B26: =COUNTIF('Call List'!$M$2:$M$44,A26) -> 0
A27: Unknown | B27: =COUNTIF('Call List'!$M$2:$M$44,A27) -> 0
A28: Not mobile friendly | B28: =COUNTIF('Call List'!$N$2:$N$44,"No") -> 0
A30: OWNER RESEARCH
A31: Owner name filled | B31: =COUNTA('Call List'!$A$2:$A$44) -> 0
A32: Still blank | B32: =43-B31 -> 43
A34: PIPELINE
A35: Not called | B35: =COUNTIF('Call List'!$X$2:$X$44,A35) -> 43
A36: No answer | B36: =COUNTIF('Call List'!$X$2:$X$44,A36) -> 0
A37: Voicemail | B37: =COUNTIF('Call List'!$X$2:$X$44,A37) -> 0
A38: Gatekeeper | B38: =COUNTIF('Call List'!$X$2:$X$44,A38) -> 0
A39: Reached owner | B39: =COUNTIF('Call List'!$X$2:$X$44,A39) -> 0
A40: Booked call | B40: =COUNTIF('Call List'!$X$2:$X$44,A40) -> 0
A41: Not interested | B41: =COUNTIF('Call List'!$X$2:$X$44,A41) -> 0
A42: Do not call | B42: =COUNTIF('Call List'!$X$2:$X$44,A42) -> 0
A43: Bad number | B43: =COUNTIF('Call List'!$X$2:$X$44,A43) -> 0
A45: KEY RATIOS
A46: Total dials logged | B46: =SUM('Call List'!$Y$2:$Y$44) -> 0
...

Sheet Rejected
A1: Business Name | B1: Category | C1: Website | D1: Reviews | E1: Rejected Because
A2: Epicurean Hotel, Autograph Collection | B2: Hotel | C2: https://www.marriott.com/en-us/hotels/tpaak-epicurean-hotel-autograph-collection/overview/?scid=f2ae0541-1279-4f24-b197-a979c79310b0 | D2: 1578 | E2: chain / franchise
A3: Tampa Marriott Water Street | B3: Hotel | C3: https://www.marriott.com/en-us/hotels/tpamc-tampa-marriott-water-street/overview/?scid=f2ae0541-1279-4f24-b197-a979c79310b0 | D3: 5933 | E3: chain / franchise
A4: Sleep Inn & Suites Tampa South | B4: Hotel | C4: https://www.choicehotels.com/florida/tampa/sleep-inn-hotels/fld69?mc=llgoxxpx | D4: 544 | E4: chain / franchise
A5: TownePlace Suites by Marriott Tampa South | B5: Hotel | C5: https://www.marriott.com/en-us/hotels/tpaxt-towneplace-suites-tampa-south/overview/?scid=f2ae0541-1279-4f24-b197-a979c79310b0 | D5: 337 | E5: chain / franchise
A6: JW Marriott Tampa Water Street | B6: Hotel | C6: https://www.marriott.com/en-us/hotels/tpajd-jw-marriott-tampa-water-street/overview/?scid=f2ae0541-1279-4f24-b197-a979c79310b0 | D6: 1596 | E6: chain / franchise
A7: Westin Tampa Downtown Waterside | B7: Hotel | C7: https://www.marriott.com/en-us/hotels/tpawh-westin-tampa-downtown-waterside/overview/?scid=f2ae0541-1279-4f24-b197-a979c79310b0 | D7: 2470 | E7: chain / franchise
A8: Hotel 1 | B8: Hotel | E8: no phone
A9: South Tampa Retreat - Hotel Quality Sleep - Family-Friendly | B9: Cottage | C9: https://www.vrbo.com/pdp/lo/123211763?MDPCID=VRBO-META.HPA.WEB-ORGANIC.VR | D9: 2 | E9: no phone
A10: Holiday Inn Express & Suites Tampa-I-75 @ Bruce B. Downs by IHG | B10: Hotel | C10: https://www.ihg.com/holidayinnexpress/hotels/us/en/tampa/tpabd/hoteldetail?cm_mmc=GoogleMaps-_-EX-_-US-_-TPABD | D10: 1329 | E10: chain / franchise
A11: Embassy Suites by Hilton Tampa USF Near Busch Gardens | B11: Hotel | C11: https://www.hilton.com/en/hotels/tpafres-embassy-suites-tampa-usf-near-busch-gardens/?SEO_id=GMB-AMER-ES-TPAFRES | D11: 4023 | E11: chain / franchise
A12: Hampton Inn & Suites Tampa-North | B12: Hotel | C12: https://www.hilton.com/en/hotels/tpanohx-hampton-suites-tampa-north/?SEO_id=GMB-AMER-HX-TPANOHX | D12: 1399 | E12: chain / franchise
A13: SpringHill Suites by Marriott Tampa North/I-75 Tampa Palms | B13: Hotel | C13: https://www.marriott.com/en-us/hotels/tpanp-springhill-suites-tampa-north-i-75-tampa-palms/overview/?scid=f2ae0541-1279-4f24-b197-a979c79310b0 | D13: 1096 | E13: chain / franchise
A14: Comfort Inn & Suites Tampa North I-75 | B14: Hotel | C14: https://www.choicehotels.com/florida/tampa/comfort-inn-hotels/fl786?mc=llgoxxpx | D14: 40 | E14: chain / franchise
A15: Courtyard by Marriott Tampa North/I-75 Fletcher | B15: Hotel | C15: https://www.marriott.com/en-us/hotels/tpacy-courtyard-tampa-north-i-75-fletcher/overview/?scid=f2ae0541-1279-4f24-b197-a979c79310b0 | D15: 743 | E15: chain / franchise
A16: Tampa Palms Country Club | B16: Country club | C16: https://www.invitedclubs.com/clubs/tampa-palms-golf-country-club | D16: 396 | E16: not lodging
A17: Holiday Inn Tampa North by IHG | B17: Hotel | C17: https://www.ihg.com/holidayinn/hotels/us/en/tampa/tpafa/hoteldetail?cm_mmc=GoogleMaps-_-HI-_-US-_-TPAFA | D17: 312 | E17: chain / franchise
A18: Home2 Suites by Hilton Tampa USF Near Busch Gardens | B18: Hotel | C18: https://www.hilton.com/en/hotels/tpasfht-home2-suites-tampa-usf-near-busch-gardens/?SEO_id=GMB-AMER-HT-TPASFHT | D18: 1036 | E18: chain / franchise
A19: La Quinta Inn & Suites by Wyndham USF (Near Busch Gardens) | B19: Hotel | C19: https://www.wyndhamhotels.com/laquinta/tampa-florida/la-quinta-usf-near-busch-gardens/overview?CID=LC:6ysy27krtpcrqev:53065&iata=00093796 | D19: 1539 | E19: chain / franchise
A20: The Lodge at Hidden River | B20: Apartment building | C20: https://www.lodgeathiddenriverapts.com/?utm_source=google-locallisting&utm_medium=organic&utm_campaign=gmb | D20: 362 | E20: not lodging
... A32: Arbor Greene Community Center | B32: Community center | C32: http://arborgreene.com/ | D32: 214 | E32: not lodging
A33: Oxford Place At Tampa Palms | B33: Condominium complex | D33: 73 | E33: not lodging
A34: The Grand Reserve at Tampa Palms Apartments | B34: Apartment rental agency | C34: https://www.cr-grandreserveapts.com/?utm_source=GMB&utm_medium=organic | D34: 221 | E34: not lodging
A35: Enchanted Travels with Cassie | B35: Travel agency | C35: https://enchantedtravelswithcassie.com/ | D35: 12 | E35: not lodging
A36: Trails at Hunter's Lake | B36: Apartment rental agency | C36: https://trailsathunterslake.com/?ilm=obl&utm_source=gmb&utm_medium=organic | D36: 266 | E36: not lodging
A37: Grand Hampton Clubhouse | B37: Country club | C37: https://www.egrandhampton.com/ | D37: 41 | E37: not lodging
A38: Travelworld | B38: Cruise agency | C38: https://www.travelworld1.com/ | D38: 8 | E38: not lodging
A39: The Legacy at Highwoods Preserve | B39: Assisted living facility | C39: https://www.legacypreservetampa.com/ | D39: 62 | E39: not lodging
A40: Rodeway Inn Near Ybor City - Casino | B40: Hotel | C40: https://www.rodewayinntampayborcity.com/ | D40: 1835 | E40: chain / franchise
A41: Marriott Tampa Westshore | B41: Hotel | C41: https://www.marriott.com/en-us/hotels/tpawe-marriott-tampa-westshore/overview/?scid=f2ae0541-1279-4f24-b197-a979c79310b0 | D41: 2013 | E41: chain / franchise
A42: Country Inn & Suites by Radisson, RJ Stadium - Tampa Airport East | B42: Hotel | C42: https://www.choicehotels.com/florida/tampa/country-inn-suites-hotels/fld26?mc=llgoxxpx | D42: 3003 | E42: chain / franchise
A43: Econo Lodge Airport @ RJ Stadium | B43: Hotel | C43: https://www.choicehotels.com/florida/tampa/econo-lodge-hotels/fl724?mc=llgoxxpx | D43: 1366 | E43: chain / franchise
A44: Home2 Suites by Hilton Tampa Downtown Channel District | B44: Hotel | C44: https://www.hilton.com/en/hotels/tpadbht-home2-suites-tampa-downtown-channel-district/?SEO_id=GMB-AMER-HT-TPADBHT | D44: 585 | E44: chain / franchise
A45: Quality Inn & Suites Tampa near Fairgrounds and Casino | B45: Hotel | C45: https://www.choicehotels.com/florida/tampa/quality-inn-hotels/fla63?mc=llgoxxpx | D45: 2019 | E45: chain / franchise
... A77: AC Hotel Tampa Airport | B77: Hotel | C77: https://www.marriott.com/en-us/hotels/tpaac-ac-hotel-tampa-airport/overview/?scid=f2ae0541-1279-4f24-b197-a979c79310b0 | D77: 904 | E77: chain / franchise
A78: Hotel cercas de la calle armenia | B78: Hotel | D78: 1 | E78: no phone
A79: Hotel Haya | B79: Hotel | E79: no phone
A80: Hotel ORA & Private Residences | B80: Hotel | C80: https://ora-hotel.com/ | D80: 5 | E80: under 10 reviews
A81: Trabajo hotel | B81: Hotel | E81: no phone
A82: Hotel gotta | B82: Extended stay hotel | E82: no phone
...
